Произошла ошибка при подключении к сервису погоды.
Traceback (most recent call last):
  File "D:\Shamil\Shamil\django\pythonProject\.venv\Lib\site-packages\urllib3\connectionpool.py", line 536, in _make_request
    response = conn.getresponse()
               ^^^^^^^^^^^^^^^^^^
  File "D:\Shamil\Shamil\django\pythonProject\.venv\Lib\site-packages\urllib3\connection.py", line 464, in getresponse
    httplib_response = super().getresponse()
                       ^^^^^^^^^^^^^^^^^^^^^
  File "C:\Users\Zhukov\AppData\Local\Programs\Python\Python312\Lib\http\client.py", line 1428, in getresponse
    response.begin()
  File "C:\Users\Zhukov\AppData\Local\Programs\Python\Python312\Lib\http\client.py", line 331, in begin
    version, status, reason = self._read_status()
                              ^^^^^^^^^^^^^^^^^^^
  File "C:\Users\Zhukov\AppData\Local\Programs\Python\Python312\Lib\http\client.py", line 292, in _read_status
    line = str(self.fp.readline(_MAXLINE + 1), "iso-8859-1")
               ^^^^^^^^^^^^^^^^^^^^^^^^^^^^^^
  File "C:\Users\Zhukov\AppData\Local\Programs\Python\Python312\Lib\socket.py", line 707, in readinto
    return self._sock.recv_into(b)
           ^^^^^^^^^^^^^^^^^^^^^^^
TimeoutError: [WinError 10060] Попытка установить соединение была безуспешной, т.к. от другого компьютера за требуемое время не получен нужный отклик, или было разорвано уже установленное соединение из-за неверного отклика уже подключенного компьютера

The above exception was the direct cause of the following exception:

Traceback (most recent call last):
  File "D:\Shamil\Shamil\django\pythonProject\.venv\Lib\site-packages\requests\adapters.py", line 667, in send
    resp = conn.urlopen(
           ^^^^^^^^^^^^^
  File "D:\Shamil\Shamil\django\pythonProject\.venv\Lib\site-packages\urllib3\connectionpool.py", line 843, in urlopen
    retries = retries.increment(
              ^^^^^^^^^^^^^^^^^^
  File "D:\Shamil\Shamil\django\pythonProject\.venv\Lib\site-packages\urllib3\util\retry.py", line 474, in increment
    raise reraise(type(error), error, _stacktrace)
          ^^^^^^^^^^^^^^^^^^^^^^^^^^^^^^^^^^^^^^^^
  File "D:\Shamil\Shamil\django\pythonProject\.venv\Lib\site-packages\urllib3\util\util.py", line 39, in reraise
    raise value
  File "D:\Shamil\Shamil\django\pythonProject\.venv\Lib\site-packages\urllib3\connectionpool.py", line 789, in urlopen
    response = self._make_request(
               ^^^^^^^^^^^^^^^^^^^
  File "D:\Shamil\Shamil\django\pythonProject\.venv\Lib\site-packages\urllib3\connectionpool.py", line 538, in _make_request
    self._raise_timeout(err=e, url=url, timeout_value=read_timeout)
  File "D:\Shamil\Shamil\django\pythonProject\.venv\Lib\site-packages\urllib3\connectionpool.py", line 369, in _raise_timeout
    raise ReadTimeoutError(
urllib3.exceptions.ReadTimeoutError: HTTPConnectionPool(host='api.openweathermap.org', port=80): Read timed out. (read timeout=None)

During handling of the above exception, another exception occurred:

Traceback (most recent call last):
  File "D:\Shamil\Shamil\django\weather_site\weatherapp\views.py", line 17, in get_weather
    response = requests.get(url)
               ^^^^^^^^^^^^^^^^^
  File "D:\Shamil\Shamil\django\pythonProject\.venv\Lib\site-packages\requests\api.py", line 73, in get
    return request("get", url, params=params, **kwargs)
           ^^^^^^^^^^^^^^^^^^^^^^^^^^^^^^^^^^^^^^^^^^^^
  File "D:\Shamil\Shamil\django\pythonProject\.venv\Lib\site-packages\requests\api.py", line 59, in request
    return session.request(method=method, url=url, **kwargs)
           ^^^^^^^^^^^^^^^^^^^^^^^^^^^^^^^^^^^^^^^^^^^^^^^^^
  File "D:\Shamil\Shamil\django\pythonProject\.venv\Lib\site-packages\requests\sessions.py", line 589, in request
    resp = self.send(prep, **send_kwargs)
           ^^^^^^^^^^^^^^^^^^^^^^^^^^^^^^
  File "D:\Shamil\Shamil\django\pythonProject\.venv\Lib\site-packages\requests\sessions.py", line 703, in send
    r = adapter.send(request, **kwargs)
        ^^^^^^^^^^^^^^^^^^^^^^^^^^^^^^^
  File "D:\Shamil\Shamil\django\pythonProject\.venv\Lib\site-packages\requests\adapters.py", line 713, in send
    raise ReadTimeout(e, request=request)
requests.exceptions.ReadTimeout: HTTPConnectionPool(host='api.openweathermap.org', port=80): Read timed out. (read timeout=None)
